Workbook

Sheet Movimientos
A1: Fecha | B1: Mes | C1: Descripción | D1: Categoría | E1: Ingresos | F1: Gastos | G1: Balance | H1: Activo (solo Inversión) | J1: PANEL DE CONTROL
A2: 46235 | B2: =IF($A2="","",TEXT($A2,"mmmm yyyy")) | C2: Nómina | D2: Sueldo | E2: 1500 | G2: =IF($A2="","",$K$3+SUM($E$2:$E2)-SUM($F$2:$F2)) | J2: Mes activo | K2: 46235 | L2: ◀ cambia el mes y se actualiza todo el libro
A3: 46237 | B3: =IF($A3="","",TEXT($A3,"mmmm yyyy")) | C3: Alquiler | D3: Vivienda y Suministros | F3: 600 | G3: =IF($A3="","",$K$3+SUM($E$2:$E3)-SUM($F$2:$F3)) | J3: Saldo inicial del banco | K3: 1000 | L3: ◀ lo que tenías en la cuenta antes del primer movimiento
A4: 46239 | B4: =IF($A4="","",TEXT($A4,"mmmm yyyy")) | C4: Compra supermercado | D4: Productos Básicos | F4: 82.4 | G4: =IF($A4="","",$K$3+SUM($E$2:$E4)-SUM($F$2:$F4))
A5: 46241 | B5: =IF($A5="","",TEXT($A5,"mmmm yyyy")) | C5: Abono transporte | D5: Transporte | F5: 30 | G5: =IF($A5="","",$K$3+SUM($E$2:$E5)-SUM($F$2:$F5)) | J5: CATEGORÍA | K5: TIPO | L5: MES ACTIVO | M5: TOTAL AÑO | N5: MEDIA MENSUAL
A6: 46244 | B6: =IF($A6="","",TEXT($A6,"mmmm yyyy")) | C6: Cena con amigos | D6: Comer fuera | F6: 28.5 | G6: =IF($A6="","",$K$3+SUM($E$2:$E6)-SUM($F$2:$F6)) | J6: Sueldo | K6: Ingreso | L6: =IF($J6="","",IF($K6="Ingreso",SUMIFS($E$2:$E$501,$A$2:$A$501,">="&$K$2,$A$2:$A$501,"<"&EOMONTH($K$2,0)+1,$D$2:$D$501,$J6),SUMIFS($F$2:$F$501,$A$2:$A$501,">="&$K$2,$A$2:$A$501,"<"&EOMONTH($K$2,0)+1,$D$2:$D$501,$J6))) | M6: =IF($J6="","",IF($K6="Ingreso",SUMIFS($E$2:$E$501,$A$2:$A$501,">="&DATE(YEAR($K$2),1,1),$A$2:$A$501,"<"&DATE(YEAR($K$2)+1,1,1),$D$2:$D$501,$J6),SUMIFS($F$2:$F$501,$A$2:$A$501,">="&DATE(YEAR($K$2),1,1),$A$2:$A$501,"<"&DATE(YEAR($K$2)+1,1,1),$D$2:$D$501,$J6))) | N6: =IFERROR($M6/$L$23,0)
A7: 46246 | B7: =IF($A7="","",TEXT($A7,"mmmm yyyy")) | C7: Cine | D7: Ocio y Caprichos | F7: 9.9 | G7: =IF($A7="","",$K$3+SUM($E$2:$E7)-SUM($F$2:$F7)) | J7: Otros Ingresos | K7: Ingreso | L7: =IF($J7="","",IF($K7="Ingreso",SUMIFS($E$2:$E$501,$A$2:$A$501,">="&$K$2,$A$2:$A$501,"<"&EOMONTH($K$2,0)+1,$D$2:$D$501,$J7),SUMIFS($F$2:$F$501,$A$2:$A$501,">="&$K$2,$A$2:$A$501,"<"&EOMONTH($K$2,0)+1,$D$2:$D$501,$J7))) | M7: =IF($J7="","",IF($K7="Ingreso",SUMIFS($E$2:$E$501,$A$2:$A$501,">="&DATE(YEAR($K$2),1,1),$A$2:$A$501,"<"&DATE(YEAR($K$2)+1,1,1),$D$2:$D$501,$J7),SUMIFS($F$2:$F$501,$A$2:$A$501,">="&DATE(YEAR($K$2),1,1),$A$2:$A$501,"<"&DATE(YEAR($K$2)+1,1,1),$D$2:$D$501,$J7))) | N7: =IFERROR($M7/$L$23,0)
A8: 46249 | B8: =IF($A8="","",TEXT($A8,"mmmm yyyy")) | C8: Aportación mensual | D8: Inversión | F8: 150 | G8: =IF($A8="","",$K$3+SUM($E$2:$E8)-SUM($F$2:$F8)) | H8: Fondo indexado | J8: Productos Básicos | K8: Gasto | L8: =IF($J8="","",IF($K8="Ingreso",SUMIFS($E$2:$E$501,$A$2:$A$501,">="&$K$2,$A$2:$A$501,"<"&EOMONTH($K$2,0)+1,$D$2:$D$501,$J8),SUMIFS($F$2:$F$501,$A$2:$A$501,">="&$K$2,$A$2:$A$501,"<"&EOMONTH($K$2,0)+1,$D$2:$D$501,$J8))) | M8: =IF($J8="","",IF($K8="Ingreso",SUMIFS($E$2:$E$501,$A$2:$A$501,">="&DATE(YEAR($K$2),1,1),$A$2:$A$501,"<"&DATE(YEAR($K$2)+1,1,1),$D$2:$D$501,$J8),SUMIFS($F$2:$F$501,$A$2:$A$501,">="&DATE(YEAR($K$2),1,1),$A$2:$A$501,"<"&DATE(YEAR($K$2)+1,1,1),$D$2:$D$501,$J8))) | N8: =IFERROR($M8/$L$23,0)
A9: 46252 | B9: =IF($A9="","",TEXT($A9,"mmmm yyyy")) | C9: Luz e internet | D9: Vivienda y Suministros | F9: 65.3 | G9: =IF($A9="","",$K$3+SUM($E$2:$E9)-SUM($F$2:$F9)) | J9: Vivienda y Suministros | K9: Gasto | L9: =IF($J9="","",IF($K9="Ingreso",SUMIFS($E$2:$E$501,$A$2:$A$501,">="&$K$2,$A$2:$A$501,"<"&EOMONTH($K$2,0)+1,$D$2:$D$501,$J9),SUMIFS($F$2:$F$501,$A$2:$A$501,">="&$K$2,$A$2:$A$501,"<"&EOMONTH($K$2,0)+1,$D$2:$D$501,$J9))) | M9: =IF($J9="","",IF($K9="Ingreso",SUMIFS($E$2:$E$501,$A$2:$A$501,">="&DATE(YEAR($K$2),1,1),$A$2:$A$501,"<"&DATE(YEAR($K$2)+1,1,1),$D$2:$D$501,$J9),SUMIFS($F$2:$F$501,$A$2:$A$501,">="&DATE(YEAR($K$2),1,1),$A$2:$A$501,"<"&DATE(YEAR($K$2)+1,1,1),$D$2:$D$501,$J9))) | N9: =IFERROR($M9/$L$23,0)
A10: 46254 | B10: =IF($A10="","",TEXT($A10,"mmmm yyyy")) | C10: Compra supermercado | D10: Productos Básicos | F10: 54.2 | G10: =IF($A10="","",$K$3+SUM($E$2:$E10)-SUM($F$2:$F10)) | J10: Transporte | K10: Gasto | L10: =IF($J10="","",IF($K10="Ingreso",SUMIFS($E$2:$E$501,$A$2:$A$501,">="&$K$2,$A$2:$A$501,"<"&EOMONTH($K$2,0)+1,$D$2:$D$501,$J10),SUMIFS($F$2:$F$501,$A$2:$A$501,">="&$K$2,$A$2:$A$501,"<"&EOMONTH($K$2,0)+1,$D$2:$D$501,$J10))) | M10: =IF($J10="","",IF($K10="Ingreso",SUMIFS($E$2:$E$501,$A$2:$A$501,">="&DATE(YEAR($K$2),1,1),$A$2:$A$501,"<"&DATE(YEAR($K$2)+1,1,1),$D$2:$D$501,$J10),SUMIFS($F$2:$F$501,$A$2:$A$501,">="&DATE(YEAR($K$2),1,1),$A$2:$A$501,"<"&DATE(YEAR($K$2)+1,1,1),$D$2:$D$501,$J10))) | N10: =IFERROR($M10/$L$23,0)
A11: 46259 | B11: =IF($A11="","",TEXT($A11,"mmmm yyyy")) | C11: Farmacia | D11: Otros Gastos | F11: 12.8 | G11: =IF($A11="","",$K$3+SUM($E$2:$E11)-SUM($F$2:$F11)) | J11: Ocio y Caprichos | K11: Gasto | L11: =IF($J11="","",IF($K11="Ingreso",SUMIFS($E$2:$E$501,$A$2:$A$501,">="&$K$2,$A$2:$A$501,"<"&EOMONTH($K$2,0)+1,$D$2:$D$501,$J11),SUMIFS($F$2:$F$501,$A$2:$A$501,">="&$K$2,$A$2:$A$501,"<"&EOMONTH($K$2,0)+1,$D$2:$D$501,$J11))) | M11: =IF($J11="","",IF($K11="Ingreso",SUMIFS($E$2:$E$501,$A$2:$A$501,">="&DATE(YEAR($K$2),1,1),$A$2:$A$501,"<"&DATE(YEAR($K$2)+1,1,1),$D$2:$D$501,$J11),SUMIFS($F$2:$F$501,$A$2:$A$501,">="&DATE(YEAR($K$2),1,1),$A$2:$A$501,"<"&DATE(YEAR($K$2)+1,1,1),$D$2:$D$501,$J11))) | N11: =IFERROR($M11/$L$23,0)
B12: =IF($A12="","",TEXT($A12,"mmmm yyyy")) | G12: =IF($A12="","",$K$3+SUM($E$2:$E12)-SUM($F$2:$F12)) | J12: Comer fuera | K12: Gasto | L12: =IF($J12="","",IF($K12="Ingreso",SUMIFS($E$2:$E$501,$A$2:$A$501,">="&$K$2,$A$2:$A$501,"<"&EOMONTH($K$2,0)+1,$D$2:$D$501,$J12),SUMIFS($F$2:$F$501,$A$2:$A$501,">="&$K$2,$A$2:$A$501,"<"&EOMONTH($K$2,0)+1,$D$2:$D$501,$J12))) | M12: =IF($J12="","",IF($K12="Ingreso",SUMIFS($E$2:$E$501,$A$2:$A$501,">="&DATE(YEAR($K$2),1,1),$A$2:$A$501,"<"&DATE(YEAR($K$2)+1,1,1),$D$2:$D$501,$J12),SUMIFS($F$2:$F$501,$A$2:$A$501,">="&DATE(YEAR($K$2),1,1),$A$2:$A$501,"<"&DATE(YEAR($K$2)+1,1,1),$D$2:$D$501,$J12))) | N12: =IFERROR($M12/$L$23,0)
B13: =IF($A13="","",TEXT($A13,"mmmm yyyy")) | G13: =IF($A13="","",$K$3+SUM($E$2:$E13)-SUM($F$2:$F13)) | J13: Otros Gastos | K13: Gasto | L13: =IF($J13="","",IF($K13="Ingreso",SUMIFS($E$2:$E$501,$A$2:$A$501,">="&$K$2,$A$2:$A$501,"<"&EOMONTH($K$2,0)+1,$D$2:$D$501,$J13),SUMIFS($F$2:$F$501,$A$2:$A$501,">="&$K$2,$A$2:$A$501,"<"&EOMONTH($K$2,0)+1,$D$2:$D$501,$J13))) | M13: =IF($J13="","",IF($K13="Ingreso",SUMIFS($E$2:$E$501,$A$2:$A$501,">="&DATE(YEAR($K$2),1,1),$A$2:$A$501,"<"&DATE(YEAR($K$2)+1,1,1),$D$2:$D$501,$J13),SUMIFS($F$2:$F$501,$A$2:$A$501,">="&DATE(YEAR($K$2),1,1),$A$2:$A$501,"<"&DATE(YEAR($K$2)+1,1,1),$D$2:$D$501,$J13))) | N13: =IFERROR($M13/$L$23,0)
B14: =IF($A14="","",TEXT($A14,"mmmm yyyy")) | G14: =IF($A14="","",$K$3+SUM($E$2:$E14)-SUM($F$2:$F14)) | J14: Inversión | K14: Inversión | L14: =IF($J14="","",IF($K14="Ingreso",SUMIFS($E$2:$E$501,$A$2:$A$501,">="&$K$2,$A$2:$A$501,"<"&EOMONTH($K$2,0)+1,$D$2:$D$501,$J14),SUMIFS($F$2:$F$501,$A$2:$A$501,">="&$K$2,$A$2:$A$501,"<"&EOMONTH($K$2,0)+1,$D$2:$D$501,$J14))) | M14: =IF($J14="","",IF($K14="Ingreso",SUMIFS($E$2:$E$501,$A$2:$A$501,">="&DATE(YEAR($K$2),1,1),$A$2:$A$501,"<"&DATE(YEAR($K$2)+1,1,1),$D$2:$D$501,$J14),SUMIFS($F$2:$F$501,$A$2:$A$501,">="&DATE(YEAR($K$2),1,1),$A$2:$A$501,"<"&DATE(YEAR($K$2)+1,1,1),$D$2:$D$501,$J14))) | N14: =IFERROR($M14/$L$23,0)
B15: =IF($A15="","",TEXT($A15,"mmmm yyyy")) | G15: =IF($A15="","",$K$3+SUM($E$2:$E15)-SUM($F$2:$F15))
B16: =IF($A16="","",TEXT($A16,"mmmm yyyy")) | G16: =IF($A16="","",$K$3+SUM($E$2:$E16)-SUM($F$2:$F16)) | J16: TOTAL INGRESOS | L16: =SUMIF($K$6:$K$14,"Ingreso",L$6:L$14) | M16: =SUMIF($K$6:$K$14,"Ingreso",M$6:M$14)
B17: =IF($A17="","",TEXT($A17,"mmmm yyyy")) | G17: =IF($A17="","",$K$3+SUM($E$2:$E17)-SUM($F$2:$F17)) | J17: TOTAL GASTOS | L17: =SUMIF($K$6:$K$14,"Gasto",L$6:L$14) | M17: =SUMIF($K$6:$K$14,"Gasto",M$6:M$14)
B18: =IF($A18="","",TEXT($A18,"mmmm yyyy")) | G18: =IF($A18="","",$K$3+SUM($E$2:$E18)-SUM($F$2:$F18)) | J18: AHORRO (ingresos − gastos) | L18: =L16-L17 | M18: =M16-M17
B19: =IF($A19="","",TEXT($A19,"mmmm yyyy")) | G19: =IF($A19="","",$K$3+SUM($E$2:$E19)-SUM($F$2:$F19)) | J19: % de ahorro | L19: =IFERROR(L18/L16,0) | M19: =IFERROR(M18/M16,0)
B20: =IF($A20="","",TEXT($A20,"mmmm yyyy")) | G20: =IF($A20="","",$K$3+SUM($E$2:$E20)-SUM($F$2:$F20)) | J20: Aportado a inversión | L20: =SUMIF($K$6:$K$14,"Inversión",L$6:L$14) | M20: =SUMIF($K$6:$K$14,"Inversión",M$6:M$14)
B21: =IF($A21="","",TEXT($A21,"mmmm yyyy")) | G21: =IF($A21="","",$K$3+SUM($E$2:$E21)-SUM($F$2:$F21)) | J21: FLUJO NETO del banco | L21: =L18-L20 | M21: =M18-M20
B22: =IF($A22="","",TEXT($A22,"mmmm yyyy")) | G22: =IF($A22="","",$K$3+SUM($E$2:$E22)-SUM($F$2:$F22))
B23: =IF($A23="","",TEXT($A23,"mmmm yyyy")) | G23: =IF($A23="","",$K$3+SUM($E$2:$E23)-SUM($F$2:$F23)) | J23: Meses con datos | L23: =SUMPRODUCT(--((Resumen!$B$4:$B$15+Resumen!$C$4:$C$15+Resumen!$E$4:$E$15)>0))
B24: =IF($A24="","",TEXT($A24,"mmmm yyyy")) | G24: =IF($A24="","",$K$3+SUM($E$2:$E24)-SUM($F$2:$F24)) | J24: Saldo actual del banco | L24: =$K$3+SUM($E$2:$E$501)-SUM($F$2:$F$501)
B25: =IF($A25="","",TEXT($A25,"mmmm yyyy")) | G25: =IF($A25="","",$K$3+SUM($E$2:$E25)-SUM($F$2:$F25))
B26: =IF($A26="","",TEXT($A26,"mmmm yyyy")) | G26: =IF($A26="","",$K$3+SUM($E$2:$E26)-SUM($F$2:$F26)) | J26: CÓMO USARLO
B27: =IF($A27="","",TEXT($A27,"mmmm yyyy")) | G27: =IF($A27="","",$K$3+SUM($E$2:$E27)-SUM($F$2:$F27)) | J27: ‼ TODO LO QUE VES SON DATOS DE EJEMPLO INVENTADOS.
B28: =IF($A28="","",TEXT($A28,"mmmm yyyy")) | G28: =IF($A28="","",$K$3+SUM($E$2:$E28)-SUM($F$2:$F28)) | J28: Borra las filas 2 a 11, pon tu saldo en K3 y empieza a apuntar lo tuyo.
B29: =IF($A29="","",TEXT($A29,"mmmm yyyy")) | G29: =IF($A29="","",$K$3+SUM($E$2:$E29)-SUM($F$2:$F29)) | J29: • Rellena solo A (fecha), C (descripción), D (categoría) y el importe en E o en F.
B30: =IF($A30="","",TEXT($A30,"mmmm yyyy")) | G30: =IF($A30="","",$K$3+SUM($E$2:$E30)-SUM($F$2:$F30)) | J30: • B (Mes) y G (Balance) se calculan solos. No los toques.
B31: =IF($A31="","",TEXT($A31,"mmmm yyyy")) | G31: =IF($A31="","",$K$3+SUM($E$2:$E31)-SUM($F$2:$F31)) | J31: • En el panel solo editas las celdas amarillas: K2 (mes) y K3 (saldo inicial).
B32: =IF($A32="","",TEXT($A32,"mmmm yyyy")) | G32: =IF($A32="","",$K$3+SUM($E$2:$E32)-SUM($F$2:$F32)) | J32: • La INVERSIÓN ya no es un gasto. Va en F porque el dinero sale del banco,
B33: =IF($A33="","",TEXT($A33,"mmmm yyyy")) | G33: =IF($A33="","",$K$3+SUM($E$2:$E33)-SUM($F$2:$F33)) | J33: pero se resta aparte: «AHORRO» va sin ella, «FLUJO NETO» con ella.
B34: =IF($A34="","",TEXT($A34,"mmmm yyyy")) | G34: =IF($A34="","",$K$3+SUM($E$2:$E34)-SUM($F$2:$F34)) | J34: • Si la categoría es Inversión, elige en H a qué activo va (desplegable).
B35: =IF($A35="","",TEXT($A35,"mmmm yyyy")) | G35: =IF($A35="","",$K$3+SUM($E$2:$E35)-SUM($F$2:$F35)) | J35: • El cashback / dinero gratis NO se apunta aquí: va en la hoja Inversiones.
B36: =IF($A36="","",TEXT($A36,"mmmm yyyy")) | G36: =IF($A36="","",$K$3+SUM($E$2:$E36)-SUM($F$2:$F36)) | J36: • Para añadir una categoría escríbela en J6:J14 y ponle su TIPO en K.
B37: =IF($A37="","",TEXT($A37,"mmmm yyyy")) | G37: =IF($A37="","",$K$3+SUM($E$2:$E37)-SUM($F$2:$F37))
B38: =IF($A38="","",TEXT($A38,"mmmm yyyy")) | G38: =IF($A38="","",$K$3+SUM($E$2:$E38)-SUM($F$2:$F38))
B39: =IF($A39="","",TEXT($A39,"mmmm yyyy")) | G39: =IF($A39="","",$K$3+SUM($E$2:$E39)-SUM($F$2:$F39))
B40: =IF($A40="","",TEXT($A40,"mmmm yyyy")) | G40: =IF($A40="","",$K$3+SUM($E$2:$E40)-SUM($F$2:$F40))
...

Sheet Resumen
A1: RESUMEN ANUAL | H1: Año: | I1: =YEAR(Movimientos!$K$2)
A2: El año sale de Movimientos!K2. Cámbialo allí para ver otro año.
A3: MES | B3: INGRESOS | C3: GASTOS | D3: AHORRO | E3: INVERSIÓN | F3: SALDO DEL BANCO | H3: GASTO POR CATEGORÍA | I3: TOTAL AÑO | J3: % DEL TOTAL | M3: Etiquetas gráficos
A4: =DATE($I$1,1,1) | B4: =SUMIFS(Movimientos!$E$2:$E$501,Movimientos!$A$2:$A$501,">="&DATE($I$1,1,1),Movimientos!$A$2:$A$501,"<"&DATE($I$1,2,1)) | C4: =SUMIFS(Movimientos!$F$2:$F$501,Movimientos!$A$2:$A$501,">="&DATE($I$1,1,1),Movimientos!$A$2:$A$501,"<"&DATE($I$1,2,1),Movimientos!$D$2:$D$501,"<>"&Movimientos!$J$14) | D4: =B4-C4 | E4: =SUMIFS(Movimientos!$F$2:$F$501,Movimientos!$A$2:$A$501,">="&DATE($I$1,1,1),Movimientos!$A$2:$A$501,"<"&DATE($I$1,2,1),Movimientos!$D$2:$D$501,Movimientos!$J$14) | F4: =Movimientos!$K$3+SUMIFS(Movimientos!$E$2:$E$501,Movimientos!$A$2:$A$501,"<"&DATE($I$1,2,1))-SUMIFS(Movimientos!$F$2:$F$501,Movimientos!$A$2:$A$501,"<"&DATE($I$1,2,1)) | H4: =Movimientos!$J$8 | I4: =Movimientos!$M$8 | J4: =IFERROR(I4/$I$10,0) | M4: =TEXT(A4,"mmm")
A5: =DATE($I$1,2,1) | B5: =SUMIFS(Movimientos!$E$2:$E$501,Movimientos!$A$2:$A$501,">="&DATE($I$1,2,1),Movimientos!$A$2:$A$501,"<"&DATE($I$1,3,1)) | C5: =SUMIFS(Movimientos!$F$2:$F$501,Movimientos!$A$2:$A$501,">="&DATE($I$1,2,1),Movimientos!$A$2:$A$501,"<"&DATE($I$1,3,1),Movimientos!$D$2:$D$501,"<>"&Movimientos!$J$14) | D5: =B5-C5 | E5: =SUMIFS(Movimientos!$F$2:$F$501,Movimientos!$A$2:$A$501,">="&DATE($I$1,2,1),Movimientos!$A$2:$A$501,"<"&DATE($I$1,3,1),Movimientos!$D$2:$D$501,Movimientos!$J$14) | F5: =Movimientos!$K$3+SUMIFS(Movimientos!$E$2:$E$501,Movimientos!$A$2:$A$501,"<"&DATE($I$1,3,1))-SUMIFS(Movimientos!$F$2:$F$501,Movimientos!$A$2:$A$501,"<"&DATE($I$1,3,1)) | H5: =Movimientos!$J$9 | I5: =Movimientos!$M$9 | J5: =IFERROR(I5/$I$10,0) | M5: =TEXT(A5,"mmm")
A6: =DATE($I$1,3,1) | B6: =SUMIFS(Movimientos!$E$2:$E$501,Movimientos!$A$2:$A$501,">="&DATE($I$1,3,1),Movimientos!$A$2:$A$501,"<"&DATE($I$1,4,1)) | C6: =SUMIFS(Movimientos!$F$2:$F$501,Movimientos!$A$2:$A$501,">="&DATE($I$1,3,1),Movimientos!$A$2:$A$501,"<"&DATE($I$1,4,1),Movimientos!$D$2:$D$501,"<>"&Movimientos!$J$14) | D6: =B6-C6 | E6: =SUMIFS(Movimientos!$F$2:$F$501,Movimientos!$A$2:$A$501,">="&DATE($I$1,3,1),Movimientos!$A$2:$A$501,"<"&DATE($I$1,4,1),Movimientos!$D$2:$D$501,Movimientos!$J$14) | F6: =Movimientos!$K$3+SUMIFS(Movimientos!$E$2:$E$501,Movimientos!$A$2:$A$501,"<"&DATE($I$1,4,1))-SUMIFS(Movimientos!$F$2:$F$501,Movimientos!$A$2:$A$501,"<"&DATE($I$1,4,1)) | H6: =Movimientos!$J$10 | I6: =Movimientos!$M$10 | J6: =IFERROR(I6/$I$10,0) | M6: =TEXT(A6,"mmm")
A7: =DATE($I$1,4,1) | B7: =SUMIFS(Movimientos!$E$2:$E$501,Movimientos!$A$2:$A$501,">="&DATE($I$1,4,1),Movimientos!$A$2:$A$501,"<"&DATE($I$1,5,1)) | C7: =SUMIFS(Movimientos!$F$2:$F$501,Movimientos!$A$2:$A$501,">="&DATE($I$1,4,1),Movimientos!$A$2:$A$501,"<"&DATE($I$1,5,1),Movimientos!$D$2:$D$501,"<>"&Movimientos!$J$14) | D7: =B7-C7 | E7: =SUMIFS(Movimientos!$F$2:$F$501,Movimientos!$A$2:$A$501,">="&DATE($I$1,4,1),Movimientos!$A$2:$A$501,"<"&DATE($I$1,5,1),Movimientos!$D$2:$D$501,Movimientos!$J$14) | F7: =Movimientos!$K$3+SUMIFS(Movimientos!$E$2:$E$501,Movimientos!$A$2:$A$501,"<"&DATE($I$1,5,1))-SUMIFS(Movimientos!$F$2:$F$501,Movimientos!$A$2:$A$501,"<"&DATE($I$1,5,1)) | H7: =Movimientos!$J$11 | I7: =Movimientos!$M$11 | J7: =IFERROR(I7/$I$10,0) | M7: =TEXT(A7,"mmm")
A8: =DATE($I$1,5,1) | B8: =SUMIFS(Movimientos!$E$2:$E$501,Movimientos!$A$2:$A$501,">="&DATE($I$1,5,1),Movimientos!$A$2:$A$501,"<"&DATE($I$1,6,1)) | C8: =SUMIFS(Movimientos!$F$2:$F$501,Movimientos!$A$2:$A$501,">="&DATE($I$1,5,1),Movimientos!$A$2:$A$501,"<"&DATE($I$1,6,1),Movimientos!$D$2:$D$501,"<>"&Movimientos!$J$14) | D8: =B8-C8 | E8: =SUMIFS(Movimientos!$F$2:$F$501,Movimientos!$A$2:$A$501,">="&DATE($I$1,5,1),Movimientos!$A$2:$A$501,"<"&DATE($I$1,6,1),Movimientos!$D$2:$D$501,Movimientos!$J$14) | F8: =Movimientos!$K$3+SUMIFS(Movimientos!$E$2:$E$501,Movimientos!$A$2:$A$501,"<"&DATE($I$1,6,1))-SUMIFS(Movimientos!$F$2:$F$501,Movimientos!$A$2:$A$501,"<"&DATE($I$1,6,1)) | H8: =Movimientos!$J$12 | I8: =Movimientos!$M$12 | J8: =IFERROR(I8/$I$10,0) | M8: =TEXT(A8,"mmm")
A9: =DATE($I$1,6,1) | B9: =SUMIFS(Movimientos!$E$2:$E$501,Movimientos!$A$2:$A$501,">="&DATE($I$1,6,1),Movimientos!$A$2:$A$501,"<"&DATE($I$1,7,1)) | C9: =SUMIFS(Movimientos!$F$2:$F$501,Movimientos!$A$2:$A$501,">="&DATE($I$1,6,1),Movimientos!$A$2:$A$501,"<"&DATE($I$1,7,1),Movimientos!$D$2:$D$501,"<>"&Movimientos!$J$14) | D9: =B9-C9 | E9: =SUMIFS(Movimientos!$F$2:$F$501,Movimientos!$A$2:$A$501,">="&DATE($I$1,6,1),Movimientos!$A$2:$A$501,"<"&DATE($I$1,7,1),Movimientos!$D$2:$D$501,Movimientos!$J$14) | F9: =Movimientos!$K$3+SUMIFS(Movimientos!$E$2:$E$501,Movimientos!$A$2:$A$501,"<"&DATE($I$1,7,1))-SUMIFS(Movimientos!$F$2:$F$501,Movimientos!$A$2:$A$501,"<"&DATE($I$1,7,1)) | H9: =Movimientos!$J$13 | I9: =Movimientos!$M$13 | J9: =IFERROR(I9/$I$10,0) | M9: =TEXT(A9,"mmm")
A10: =DATE($I$1,7,1) | B10: =SUMIFS(Movimientos!$E$2:$E$501,Movimientos!$A$2:$A$501,">="&DATE($I$1,7,1),Movimientos!$A$2:$A$501,"<"&DATE($I$1,8,1)) | C10: =SUMIFS(Movimientos!$F$2:$F$501,Movimientos!$A$2:$A$501,">="&DATE($I$1,7,1),Movimientos!$A$2:$A$501,"<"&DATE($I$1,8,1),Movimientos!$D$2:$D$501,"<>"&Movimientos!$J$14) | D10: =B10-C10 | E10: =SUMIFS(Movimientos!$F$2:$F$501,Movimientos!$A$2:$A$501,">="&DATE($I$1,7,1),Movimientos!$A$2:$A$501,"<"&DATE($I$1,8,1),Movimientos!$D$2:$D$501,Movimientos!$J$14) | F10: =Movimientos!$K$3+SUMIFS(Movimientos!$E$2:$E$501,Movimientos!$A$2:$A$501,"<"&DATE($I$1,8,1))-SUMIFS(Movimientos!$F$2:$F$501,Movimientos!$A$2:$A$501,"<"&DATE($I$1,8,1)) | H10: TOTAL GASTOS | I10: =SUM(I4:I9) | J10: =IFERROR(SUM(J4:J9),0) | M10: =TEXT(A10,"mmm")
A11: =DATE($I$1,8,1) | B11: =SUMIFS(Movimientos!$E$2:$E$501,Movimientos!$A$2:$A$501,">="&DATE($I$1,8,1),Movimientos!$A$2:$A$501,"<"&DATE($I$1,9,1)) | C11: =SUMIFS(Movimientos!$F$2:$F$501,Movimientos!$A$2:$A$501,">="&DATE($I$1,8,1),Movimientos!$A$2:$A$501,"<"&DATE($I$1,9,1),Movimientos!$D$2:$D$501,"<>"&Movimientos!$J$14) | D11: =B11-C11 | E11: =SUMIFS(Movimientos!$F$2:$F$501,Movimientos!$A$2:$A$501,">="&DATE($I$1,8,1),Movimientos!$A$2:$A$501,"<"&DATE($I$1,9,1),Movimientos!$D$2:$D$501,Movimientos!$J$14) | F11: =Movimientos!$K$3+SUMIFS(Movimientos!$E$2:$E$501,Movimientos!$A$2:$A$501,"<"&DATE($I$1,9,1))-SUMIFS(Movimientos!$F$2:$F$501,Movimientos!$A$2:$A$501,"<"&DATE($I$1,9,1)) | H11: Cuadre (debe ser 0) | I11: =I10-C16 | M11: =TEXT(A11,"mmm")
A12: =DATE($I$1,9,1) | B12: =SUMIFS(Movimientos!$E$2:$E$501,Movimientos!$A$2:$A$501,">="&DATE($I$1,9,1),Movimientos!$A$2:$A$501,"<"&DATE($I$1,10,1)) | C12: =SUMIFS(Movimientos!$F$2:$F$501,Movimientos!$A$2:$A$501,">="&DATE($I$1,9,1),Movimientos!$A$2:$A$501,"<"&DATE($I$1,10,1),Movimientos!$D$2:$D$501,"<>"&Movimientos!$J$14) | D12: =B12-C12 | E12: =SUMIFS(Movimientos!$F$2:$F$501,Movimientos!$A$2:$A$501,">="&DATE($I$1,9,1),Movimientos!$A$2:$A$501,"<"&DATE($I$1,10,1),Movimientos!$D$2:$D$501,Movimientos!$J$14) | F12: =Movimientos!$K$3+SUMIFS(Movimientos!$E$2:$E$501,Movimientos!$A$2:$A$501,"<"&DATE($I$1,10,1))-SUMIFS(Movimientos!$F$2:$F$501,Movimientos!$A$2:$A$501,"<"&DATE($I$1,10,1)) | M12: =TEXT(A12,"mmm")
A13: =DATE($I$1,10,1) | B13: =SUMIFS(Movimientos!$E$2:$E$501,Movimientos!$A$2:$A$501,">="&DATE($I$1,10,1),Movimientos!$A$2:$A$501,"<"&DATE($I$1,11,1)) | C13: =SUMIFS(Movimientos!$F$2:$F$501,Movimientos!$A$2:$A$501,">="&DATE($I$1,10,1),Movimientos!$A$2:$A$501,"<"&DATE($I$1,11,1),Movimientos!$D$2:$D$501,"<>"&Movimientos!$J$14) | D13: =B13-C13 | E13: =SUMIFS(Movimientos!$F$2:$F$501,Movimientos!$A$2:$A$501,">="&DATE($I$1,10,1),Movimientos!$A$2:$A$501,"<"&DATE($I$1,11,1),Movimientos!$D$2:$D$501,Movimientos!$J$14) | F13: =Movimientos!$K$3+SUMIFS(Movimientos!$E$2:$E$501,Movimientos!$A$2:$A$501,"<"&DATE($I$1,11,1))-SUMIFS(Movimientos!$F$2:$F$501,Movimientos!$A$2:$A$501,"<"&DATE($I$1,11,1)) | H13: INGRESO POR CATEGORÍA | I13: TOTAL AÑO | J13: % DEL TOTAL | M13: =TEXT(A13,"mmm")
A14: =DATE($I$1,11,1) | B14: =SUMIFS(Movimientos!$E$2:$E$501,Movimientos!$A$2:$A$501,">="&DATE($I$1,11,1),Movimientos!$A$2:$A$501,"<"&DATE($I$1,12,1)) | C14: =SUMIFS(Movimientos!$F$2:$F$501,Movimientos!$A$2:$A$501,">="&DATE($I$1,11,1),Movimientos!$A$2:$A$501,"<"&DATE($I$1,12,1),Movimientos!$D$2:$D$501,"<>"&Movimientos!$J$14) | D14: =B14-C14 | E14: =SUMIFS(Movimientos!$F$2:$F$501,Movimientos!$A$2:$A$501,">="&DATE($I$1,11,1),Movimientos!$A$2:$A$501,"<"&DATE($I$1,12,1),Movimientos!$D$2:$D$501,Movimientos!$J$14) | F14: =Movimientos!$K$3+SUMIFS(Movimientos!$E$2:$E$501,Movimientos!$A$2:$A$501,"<"&DATE($I$1,12,1))-SUMIFS(Movimientos!$F$2:$F$501,Movimientos!$A$2:$A$501,"<"&DATE($I$1,12,1)) | H14: =Movimientos!$J$6 | I14: =Movimientos!$M$6 | J14: =IFERROR(I14/$I$16,0) | M14: =TEXT(A14,"mmm")
A15: =DATE($I$1,12,1) | B15: =SUMIFS(Movimientos!$E$2:$E$501,Movimientos!$A$2:$A$501,">="&DATE($I$1,12,1),Movimientos!$A$2:$A$501,"<"&DATE($I$1,13,1)) | C15: =SUMIFS(Movimientos!$F$2:$F$501,Movimientos!$A$2:$A$501,">="&DATE($I$1,12,1),Movimientos!$A$2:$A$501,"<"&DATE($I$1,13,1),Movimientos!$D$2:$D$501,"<>"&Movimientos!$J$14) | D15: =B15-C15 | E15: =SUMIFS(Movimientos!$F$2:$F$501,Movimientos!$A$2:$A$501,">="&DATE($I$1,12,1),Movimientos!$A$2:$A$501,"<"&DATE($I$1,13,1),Movimientos!$D$2:$D$501,Movimientos!$J$14) | F15: =Movimientos!$K$3+SUMIFS(Movimientos!$E$2:$E$501,Movimientos!$A$2:$A$501,"<"&DATE($I$1,13,1))-SUMIFS(Movimientos!$F$2:$F$501,Movimientos!$A$2:$A$501,"<"&DATE($I$1,13,1)) | H15: =Movimientos!$J$7 | I15: =Movimientos!$M$7 | J15: =IFERROR(I15/$I$16,0) | M15: =TEXT(A15,"mmm")
A16: TOTAL AÑO | B16: =SUM(B4:B15) | C16: =SUM(C4:C15) | D16: =SUM(D4:D15) | E16: =SUM(E4:E15) | F16: =Movimientos!$L$24 | H16: TOTAL INGRESOS | I16: =SUM(I14:I15) | J16: =IFERROR(SUM(J14:J15),0)
A18: INDICADOR | B18: VALOR
A19: Saldo actual del banco | B19: =Movimientos!$L$24
A20: Ahorro medio mensual | B20: =IFERROR($D$16/Movimientos!$L$23,0)
A21: Gasto medio mensual | B21: =IFERROR($C$16/Movimientos!$L$23,0)
A22: Tasa de ahorro del año | B22: =IFERROR($D$16/$B$16,0)
A23: Mes de mayor gasto | B23: =IFERROR(TEXT(INDEX($A$4:$A$15,MATCH(MAX($C$4:$C$15),$C$4:$C$15,0)),"mmmm"),"")
A24: Meses de colchón | B24: =IFERROR(Movimientos!$L$24/($C$16/Movimientos!$L$23),0)
A25: Aportado a inversión (año) | B25: =$E$16
A26: Total aportado a la cartera | B26: =Inversiones!$E$16
A27: Valor de la cartera | B27: =Inversiones!$F$16
A28: Generado por el mercado | B28: =Inversiones!$G$16
A29: Patrimonio (banco + cartera) | B29: =Movimientos!$L$24+Inversiones!$F$16

Sheet Presupuesto
A1: PRESUPUESTO MENSUAL
A2: Rellena solo la columna amarilla. El mes es el de Movimientos!K2.
A4: CATEGORÍA | B4: PRESUPUESTO | C4: GASTO REAL | D4: DISPONIBLE | E4: % CONSUMIDO
A5: =Movimientos!$J$8 | B5: 150 | C5: =Movimientos!$L$8 | D5: =B5-C5 | E5: =IFERROR(C5/B5,0)
A6: =Movimientos!$J$9 | B6: 700 | C6: =Movimientos!$L$9 | D6: =B6-C6 | E6: =IFERROR(C6/B6,0)
A7: =Movimientos!$J$10 | B7: 40 | C7: =Movimientos!$L$10 | D7: =B7-C7 | E7: =IFERROR(C7/B7,0)
A8: =Movimientos!$J$11 | B8: 80 | C8: =Movimientos!$L$11 | D8: =B8-C8 | E8: =IFERROR(C8/B8,0)
A9: =Movimientos!$J$12 | B9: 100 | C9: =Movimientos!$L$12 | D9: =B9-C9 | E9: =IFERROR(C9/B9,0)
A10: =Movimientos!$J$13 | B10: 50 | C10: =Movimientos!$L$13 | D10: =B10-C10 | E10: =IFERROR(C10/B10,0)
A11: TOTAL | B11: =SUM(B5:B10) | C11: =SUM(C5:C10) | D11: =SUM(D5:D10) | E11: =IFERROR(C11/B11,0)
A13: Ingresos del mes | B13: =Movimientos!$L$16
A14: Margen (ingresos − presupuesto) | B14: =B13-B11
A15: Objetivo de inversión mensual | B15: 150 | C15: ◀ cuánto quieres invertir al mes (ya no cuenta como gasto)
A16: Aportado este mes | B16: =Movimientos!$L$20
A17: Pendiente de aportar | B17: =MAX(0,B15-B16)

Sheet Inversiones
A1: CARTERA DE INVERSIÓN | K1: HISTÓRICO DE LA CARTERA
A2: Tres formas distintas de que entre dinero en la cartera, y solo una de ellas es rentabilidad. Las tres se suman en TOTAL APORTADO. | K2: Cada cierto tiempo (p. ej. a fin de mes) apunta la fecha y lo que vale la cartera entera. El aportado se calcula solo.
A3: GENERADO POR EL MERCADO = Valor de mercado − Total aportado. Ni lo que metes tú ni el cashback cuentan nunca como ganancia de la inversión.
A5: ACTIVO | B5: 1· APORTACIÓN INICIAL | C5: 2· APORTADO DEL BANCO | D5: 3· APORTADO GRATIS | E5: TOTAL APORTADO | F5: VALOR DE MERCADO | G5: GENERADO POR EL MERCADO | H5: RENTAB. % | I5: ÚLTIMA VALORACIÓN | K5: FECHA | L5: APORTADO ACUMULADO | M5: VALOR DE MERCADO | N5: GENERADO
A6: Fondo indexado | B6: 100 | C6: =IF($A6="","",SUMIFS(Movimientos!$F$2:$F$501,Movimientos!$D$2:$D$501,Movimientos!$J$14,Movimientos!$H$2:$H$501,$A6)) | D6: =IF($A6="","",SUMIFS($D$37:$D$96,$B$37:$B$96,$A6)) | E6: =IF($A6="","",$B6+$C6+$D6) | F6: 265 | G6: =IF($A6="","",$F6-$E6) | H6: =IF(OR($A6="",$E6=0),"",$G6/$E6) | I6: 46265 | K6: 46265 | L6: =IF($K6="","",$B$16+SUMIFS(Movimientos!$F$2:$F$501,Movimientos!$D$2:$D$501,Movimientos!$J$14,Movimientos!$A$2:$A$501,"<="&$K6)+SUMIFS($D$37:$D$96,$A$37:$A$96,"<="&$K6)) | M6: 265 | N6: =IF($K6="","",$M6-$L6)
C7: =IF($A7="","",SUMIFS(Movimientos!$F$2:$F$501,Movimientos!$D$2:$D$501,Movimientos!$J$14,Movimientos!$H$2:$H$501,$A7)) | D7: =IF($A7="","",SUMIFS($D$37:$D$96,$B$37:$B$96,$A7)) | E7: =IF($A7="","",$B7+$C7+$D7) | G7: =IF($A7="","",$F7-$E7) | H7: =IF(OR($A7="",$E7=0),"",$G7/$E7) | L7: =IF($K7="","",$B$16+SUMIFS(Movimientos!$F$2:$F$501,Movimientos!$D$2:$D$501,Movimientos!$J$14,Movimientos!$A$2:$A$501,"<="&$K7)+SUMIFS($D$37:$D$96,$A$37:$A$96,"<="&$K7)) | N7: =IF($K7="","",$M7-$L7)
C8: =IF($A8="","",SUMIFS(Movimientos!$F$2:$F$501,Movimientos!$D$2:$D$501,Movimientos!$J$14,Movimientos!$H$2:$H$501,$A8)) | D8: =IF($A8="","",SUMIFS($D$37:$D$96,$B$37:$B$96,$A8)) | E8: =IF($A8="","",$B8+$C8+$D8) | G8: =IF($A8="","",$F8-$E8) | H8: =IF(OR($A8="",$E8=0),"",$G8/$E8) | L8: =IF($K8="","",$B$16+SUMIFS(Movimientos!$F$2:$F$501,Movimientos!$D$2:$D$501,Movimientos!$J$14,Movimientos!$A$2:$A$501,"<="&$K8)+SUMIFS($D$37:$D$96,$A$37:$A$96,"<="&$K8)) | N8: =IF($K8="","",$M8-$L8)
C9: =IF($A9="","",SUMIFS(Movimientos!$F$2:$F$501,Movimientos!$D$2:$D$501,Movimientos!$J$14,Movimientos!$H$2:$H$501,$A9)) | D9: =IF($A9="","",SUMIFS($D$37:$D$96,$B$37:$B$96,$A9)) | E9: =IF($A9="","",$B9+$C9+$D9) | G9: =IF($A9="","",$F9-$E9) | H9: =IF(OR($A9="",$E9=0),"",$G9/$E9) | L9: =IF($K9="","",$B$16+SUMIFS(Movimientos!$F$2:$F$501,Movimientos!$D$2:$D$501,Movimientos!$J$14,Movimientos!$A$2:$A$501,"<="&$K9)+SUMIFS($D$37:$D$96,$A$37:$A$96,"<="&$K9)) | N9: =IF($K9="","",$M9-$L9)
C10: =IF($A10="","",SUMIFS(Movimientos!$F$2:$F$501,Movimientos!$D$2:$D$501,Movimientos!$J$14,Movimientos!$H$2:$H$501,$A10)) | D10: =IF($A10="","",SUMIFS($D$37:$D$96,$B$37:$B$96,$A10)) | E10: =IF($A10="","",$B10+$C10+$D10) | G10: =IF($A10="","",$F10-$E10) | H10: =IF(OR($A10="",$E10=0),"",$G10/$E10) | L10: =IF($K10="","",$B$16+SUMIFS(Movimientos!$F$2:$F$501,Movimientos!$D$2:$D$501,Movimientos!$J$14,Movimientos!$A$2:$A$501,"<="&$K10)+SUMIFS($D$37:$D$96,$A$37:$A$96,"<="&$K10)) | N10: =IF($K10="","",$M10-$L10)
C11: =IF($A11="","",SUMIFS(Movimientos!$F$2:$F$501,Movimientos!$D$2:$D$501,Movimientos!$J$14,Movimientos!$H$2:$H$501,$A11)) | D11: =IF($A11="","",SUMIFS($D$37:$D$96,$B$37:$B$96,$A11)) | E11: =IF($A11="","",$B11+$C11+$D11) | G11: =IF($A11="","",$F11-$E11) | H11: =IF(OR($A11="",$E11=0),"",$G11/$E11) | L11: =IF($K11="","",$B$16+SUMIFS(Movimientos!$F$2:$F$501,Movimientos!$D$2:$D$501,Movimientos!$J$14,Movimientos!$A$2:$A$501,"<="&$K11)+SUMIFS($D$37:$D$96,$A$37:$A$96,"<="&$K11)) | N11: =IF($K11="","",$M11-$L11)
C12: =IF($A12="","",SUMIFS(Movimientos!$F$2:$F$501,Movimientos!$D$2:$D$501,Movimientos!$J$14,Movimientos!$H$2:$H$501,$A12)) | D12: =IF($A12="","",SUMIFS($D$37:$D$96,$B$37:$B$96,$A12)) | E12: =IF($A12="","",$B12+$C12+$D12) | G12: =IF($A12="","",$F12-$E12) | H12: =IF(OR($A12="",$E12=0),"",$G12/$E12) | L12: =IF($K12="","",$B$16+SUMIFS(Movimientos!$F$2:$F$501,Movimientos!$D$2:$D$501,Movimientos!$J$14,Movimientos!$A$2:$A$501,"<="&$K12)+SUMIFS($D$37:$D$96,$A$37:$A$96,"<="&$K12)) | N12: =IF($K12="","",$M12-$L12)
C13: =IF($A13="","",SUMIFS(Movimientos!$F$2:$F$501,Movimientos!$D$2:$D$501,Movimientos!$J$14,Movimientos!$H$2:$H$501,$A13)) | D13: =IF($A13="","",SUMIFS($D$37:$D$96,$B$37:$B$96,$A13)) | E13: =IF($A13="","",$B13+$C13+$D13) | G13: =IF($A13="","",$F13-$E13) | H13: =IF(OR($A13="",$E13=0),"",$G13/$E13) | L13: =IF($K13="","",$B$16+SUMIFS(Movimientos!$F$2:$F$501,Movimientos!$D$2:$D$501,Movimientos!$J$14,Movimientos!$A$2:$A$501,"<="&$K13)+SUMIFS($D$37:$D$96,$A$37:$A$96,"<="&$K13)) | N13: =IF($K13="","",$M13-$L13)
C14: =IF($A14="","",SUMIFS(Movimientos!$F$2:$F$501,Movimientos!$D$2:$D$501,Movimientos!$J$14,Movimientos!$H$2:$H$501,$A14)) | D14: =IF($A14="","",SUMIFS($D$37:$D$96,$B$37:$B$96,$A14)) | E14: =IF($A14="","",$B14+$C14+$D14) | G14: =IF($A14="","",$F14-$E14) | H14: =IF(OR($A14="",$E14=0),"",$G14/$E14) | L14: =IF($K14="","",$B$16+SUMIFS(Movimientos!$F$2:$F$501,Movimientos!$D$2:$D$501,Movimientos!$J$14,Movimientos!$A$2:$A$501,"<="&$K14)+SUMIFS($D$37:$D$96,$A$37:$A$96,"<="&$K14)) | N14: =IF($K14="","",$M14-$L14)
C15: =IF($A15="","",SUMIFS(Movimientos!$F$2:$F$501,Movimientos!$D$2:$D$501,Movimientos!$J$14,Movimientos!$H$2:$H$501,$A15)) | D15: =IF($A15="","",SUMIFS($D$37:$D$96,$B$37:$B$96,$A15)) | E15: =IF($A15="","",$B15+$C15+$D15) | G15: =IF($A15="","",$F15-$E15) | H15: =IF(OR($A15="",$E15=0),"",$G15/$E15) | L15: =IF($K15="","",$B$16+SUMIFS(Movimientos!$F$2:$F$501,Movimientos!$D$2:$D$501,Movimientos!$J$14,Movimientos!$A$2:$A$501,"<="&$K15)+SUMIFS($D$37:$D$96,$A$37:$A$96,"<="&$K15)) | N15: =IF($K15="","",$M15-$L15)
A16: TOTAL CARTERA | B16: =SUM(B6:B15) | C16: =SUM(C6:C15) | D16: =SUM(D6:D15) | E16: =SUM(E6:E15) | F16: =SUM(F6:F15) | G16: =F16-E16 | H16: =IFERROR(G16/E16,0) | L16: =IF($K16="","",$B$16+SUMIFS(Movimientos!$F$2:$F$501,Movimientos!$D$2:$D$501,Movimientos!$J$14,Movimientos!$A$2:$A$501,"<="&$K16)+SUMIFS($D$37:$D$96,$A$37:$A$96,"<="&$K16)) | N16: =IF($K16="","",$M16-$L16)
L17: =IF($K17="","",$B$16+SUMIFS(Movimientos!$F$2:$F$501,Movimientos!$D$2:$D$501,Movimientos!$J$14,Movimientos!$A$2:$A$501,"<="&$K17)+SUMIFS($D$37:$D$96,$A$37:$A$96,"<="&$K17)) | N17: =IF($K17="","",$M17-$L17)
A18: Aportado del banco sin asignar a un activo | B18: =SUMIFS(Movimientos!$F$2:$F$501,Movimientos!$D$2:$D$501,Movimientos!$J$14)-C16 | C18: ◀ si no es 0, rellena la columna «Activo» en Movimientos | L18: =IF($K18="","",$B$16+SUMIFS(Movimientos!$F$2:$F$501,Movimientos!$D$2:$D$501,Movimientos!$J$14,Movimientos!$A$2:$A$501,"<="&$K18)+SUMIFS($D$37:$D$96,$A$37:$A$96,"<="&$K18)) | N18: =IF($K18="","",$M18-$L18)
A19: Cashback sin asignar a un activo | B19: =SUM($D$37:$D$96)-D16 | C19: ◀ si no es 0, rellena la columna «Activo» del registro de abajo | L19: =IF($K19="","",$B$16+SUMIFS(Movimientos!$F$2:$F$501,Movimientos!$D$2:$D$501,Movimientos!$J$14,Movimientos!$A$2:$A$501,"<="&$K19)+SUMIFS($D$37:$D$96,$A$37:$A$96,"<="&$K19)) | N19: =IF($K19="","",$M19-$L19)
L20: =IF($K20="","",$B$16+SUMIFS(Movimientos!$F$2:$F$501,Movimientos!$D$2:$D$501,Movimientos!$J$14,Movimientos!$A$2:$A$501,"<="&$K20)+SUMIFS($D$37:$D$96,$A$37:$A$96,"<="&$K20)) | N20: =IF($K20="","",$M20-$L20)
A21: INDICADOR | B21: VALOR | L21: =IF($K21="","",$B$16+SUMIFS(Movimientos!$F$2:$F$501,Movimientos!$D$2:$D$501,Movimientos!$J$14,Movimientos!$A$2:$A$501,"<="&$K21)+SUMIFS($D$37:$D$96,$A$37:$A$96,"<="&$K21)) | N21: =IF($K21="","",$M21-$L21)
A22: 1· Aportación inicial (antes del registro) | B22: =B16 | L22: =IF($K22="","",$B$16+SUMIFS(Movimientos!$F$2:$F$501,Movimientos!$D$2:$D$501,Movimientos!$J$14,Movimientos!$A$2:$A$501,"<="&$K22)+SUMIFS($D$37:$D$96,$A$37:$A$96,"<="&$K22)) | N22: =IF($K22="","",$M22-$L22)
A23: 2· Aportado desde el banco | B23: =C16 | L23: =IF($K23="","",$B$16+SUMIFS(Movimientos!$F$2:$F$501,Movimientos!$D$2:$D$501,Movimientos!$J$14,Movimientos!$A$2:$A$501,"<="&$K23)+SUMIFS($D$37:$D$96,$A$37:$A$96,"<="&$K23)) | N23: =IF($K23="","",$M23-$L23)
A24: 3· Aportado gratis (cashback y promos) | B24: =D16 | L24: =IF($K24="","",$B$16+SUMIFS(Movimientos!$F$2:$F$501,Movimientos!$D$2:$D$501,Movimientos!$J$14,Movimientos!$A$2:$A$501,"<="&$K24)+SUMIFS($D$37:$D$96,$A$37:$A$96,"<="&$K24)) | N24: =IF($K24="","",$M24-$L24)
A25: TOTAL APORTADO (1+2+3) | B25: =E16 | L25: =IF($K25="","",$B$16+SUMIFS(Movimientos!$F$2:$F$501,Movimientos!$D$2:$D$501,Movimientos!$J$14,Movimientos!$A$2:$A$501,"<="&$K25)+SUMIFS($D$37:$D$96,$A$37:$A$96,"<="&$K25)) | N25: =IF($K25="","",$M25-$L25)
A26: Valor de mercado hoy | B26: =F16 | L26: =IF($K26="","",$B$16+SUMIFS(Movimientos!$F$2:$F$501,Movimientos!$D$2:$D$501,Movimientos!$J$14,Movimientos!$A$2:$A$501,"<="&$K26)+SUMIFS($D$37:$D$96,$A$37:$A$96,"<="&$K26)) | N26: =IF($K26="","",$M26-$L26)
A27: GENERADO POR EL MERCADO | B27: =G16 | L27: =IF($K27="","",$B$16+SUMIFS(Movimientos!$F$2:$F$501,Movimientos!$D$2:$D$501,Movimientos!$J$14,Movimientos!$A$2:$A$501,"<="&$K27)+SUMIFS($D$37:$D$96,$A$37:$A$96,"<="&$K27)) | N27: =IF($K27="","",$M27-$L27)
A28: Rentabilidad del mercado | B28: =H16 | L28: =IF($K28="","",$B$16+SUMIFS(Movimientos!$F$2:$F$501,Movimientos!$D$2:$D$501,Movimientos!$J$14,Movimientos!$A$2:$A$501,"<="&$K28)+SUMIFS($D$37:$D$96,$A$37:$A$96,"<="&$K28)) | N28: =IF($K28="","",$M28-$L28)
A29: Ganado sin poner dinero (mercado + gratis) | B29: =G16+D16 | L29: =IF($K29="","",$B$16+SUMIFS(Movimientos!$F$2:$F$501,Movimientos!$D$2:$D$501,Movimientos!$J$14,Movimientos!$A$2:$A$501,"<="&$K29)+SUMIFS($D$37:$D$96,$A$37:$A$96,"<="&$K29)) | N29: =IF($K29="","",$M29-$L29)
A30: Aportado del banco este año | B30: =SUMIF(Movimientos!$K$6:$K$14,"Inversión",Movimientos!$M$6:$M$14) | L30: =IF($K30="","",$B$16+SUMIFS(Movimientos!$F$2:$F$501,Movimientos!$D$2:$D$501,Movimientos!$J$14,Movimientos!$A$2:$A$501,"<="&$K30)+SUMIFS($D$37:$D$96,$A$37:$A$96,"<="&$K30)) | N30: =IF($K30="","",$M30-$L30)
A31: Aportado del banco el mes activo | B31: =SUMIF(Movimientos!$K$6:$K$14,"Inversión",Movimientos!$L$6:$L$14) | L31: =IF($K31="","",$B$16+SUMIFS(Movimientos!$F$2:$F$501,Movimientos!$D$2:$D$501,Movimientos!$J$14,Movimientos!$A$2:$A$501,"<="&$K31)+SUMIFS($D$37:$D$96,$A$37:$A$96,"<="&$K31)) | N31: =IF($K31="","",$M31-$L31)
L32: =IF($K32="","",$B$16+SUMIFS(Movimientos!$F$2:$F$501,Movimientos!$D$2:$D$501,Movimientos!$J$14,Movimientos!$A$2:$A$501,"<="&$K32)+SUMIFS($D$37:$D$96,$A$37:$A$96,"<="&$K32)) | N32: =IF($K32="","",$M32-$L32)
L33: =IF($K33="","",$B$16+SUMIFS(Movimientos!$F$2:$F$501,Movimientos!$D$2:$D$501,Movimientos!$J$14,Movimientos!$A$2:$A$501,"<="&$K33)+SUMIFS($D$37:$D$96,$A$37:$A$96,"<="&$K33)) | N33: =IF($K33="","",$M33-$L33)
A34: APORTACIONES GRATIS · cashback, % de tarjeta, redondeos, promos | L34: =IF($K34="","",$B$16+SUMIFS(Movimientos!$F$2:$F$501,Movimientos!$D$2:$D$501,Movimientos!$J$14,Movimientos!$A$2:$A$501,"<="&$K34)+SUMIFS($D$37:$D$96,$A$37:$A$96,"<="&$K34)) | N34: =IF($K34="","",$M34-$L34)
A35: Dinero que entra en la cartera sin salir de tu cuenta. No es un ingreso ni un gasto: no toques Movimientos por esto. | L35: =IF($K35="","",$B$16+SUMIFS(Movimientos!$F$2:$F$501,Movimientos!$D$2:$D$501,Movimientos!$J$14,Movimientos!$A$2:$A$501,"<="&$K35)+SUMIFS($D$37:$D$96,$A$37:$A$96,"<="&$K35)) | N35: =IF($K35="","",$M35-$L35)
A36: FECHA | B36: ACTIVO | C36: CONCEPTO | D36: IMPORTE | F36: REGLA DE CASHBACK (solo referencia) | L36: =IF($K36="","",$B$16+SUMIFS(Movimientos!$F$2:$F$501,Movimientos!$D$2:$D$501,Movimientos!$J$14,Movimientos!$A$2:$A$501,"<="&$K36)+SUMIFS($D$37:$D$96,$A$37:$A$96,"<="&$K36)) | N36: =IF($K36="","",$M36-$L36)
A37: 46265 | B37: Fondo indexado | C37: Cashback 1% de la tarjeta | D37: 8.83 | F37: % que te devuelven | G37: 0.01 | L37: =IF($K37="","",$B$16+SUMIFS(Movimientos!$F$2:$F$501,Movimientos!$D$2:$D$501,Movimientos!$J$14,Movimientos!$A$2:$A$501,"<="&$K37)+SUMIFS($D$37:$D$96,$A$37:$A$96,"<="&$K37)) | N37: =IF($K37="","",$M37-$L37)
F38: Gasto del mes activo | G38: =Movimientos!$L$17 | L38: =IF($K38="","",$B$16+SUMIFS(Movimientos!$F$2:$F$501,Movimientos!$D$2:$D$501,Movimientos!$J$14,Movimientos!$A$2:$A$501,"<="&$K38)+SUMIFS($D$37:$D$96,$A$37:$A$96,"<="&$K38)) | N38: =IF($K38="","",$M38-$L38)
F39: ≈ te tocaría | G39: =$G$38*$G$37 | L39: =IF($K39="","",$B$16+SUMIFS(Movimientos!$F$2:$F$501,Movimientos!$D$2:$D$501,Movimientos!$J$14,Movimientos!$A$2:$A$501,"<="&$K39)+SUMIFS($D$37:$D$96,$A$37:$A$96,"<="&$K39)) | N39: =IF($K39="","",$M39-$L39)
F40: Es una estimación para cuadrar. Apunta a la izquierda lo que te llegue de verdad: eso es lo que cuenta. | L40: =IF($K40="","",$B$16+SUMIFS(Movimientos!$F$2:$F$501,Movimientos!$D$2:$D$501,Movimientos!$J$14,Movimientos!$A$2:$A$501,"<="&$K40)+SUMIFS($D$37:$D$96,$A$37:$A$96,"<="&$K40)) | N40: =IF($K40="","",$M40-$L40)
L41: =IF($K41="","",$B$16+SUMIFS(Movimientos!$F$2:$F$501,Movimientos!$D$2:$D$501,Movimientos!$J$14,Movimientos!$A$2:$A$501,"<="&$K41)+SUMIFS($D$37:$D$96,$A$37:$A$96,"<="&$K41)) | N41: =IF($K41="","",$M41-$L41)
...
